<mujoco>
    <option gravity="0 0 0" />
    <worldbody>
        <light diffuse=".5 .5 .5" pos="0 0 10" dir="0 0 -1"/>
        <geom type="plane" size="2.5 2.5 0.1" rgba=".9 .9 .9 1"/>
        <body pos=".5 0 .2" euler="0 90 0">
            <joint type="hinge" axis="-1 0 0" pos="0 0 -.5"/>
            <geom type="cylinder" size=".05 .5" rgba=".9 0 0 1"/>
            <body pos="0 0 1" euler="0 0 0">
                <joint type="hinge" axis="-1 0 0" pos="0 0 -.5"/>
                <geom type="cylinder" size=".05 .5" rgba="0 .9 0 1"/>
                <site name="tip" size=".1" pos="0 0 .5"/>
            </body>
        </body>
    </worldbody>
    <sensor>
        <framepos objtype="site" objname="tip"/>
    </sensor>
</mujoco>