<mujoco>
    <option gravity="0 0 -9.81" />
    <worldbody>
        <light diffuse=".5 .5 .5" pos="0 0 10" dir="0 0 -1" />
        <geom type="plane" size="20 20 0.1" rgba=".9 .9 .9 1" />
        <body name="chassis" pos="0 0 .2" euler="0 90 0">
            <joint type="free" />
            <geom type="box" size=".1 .2 .5" rgba=".1 .1 .1 1" />
            <site name="marker" pos="0 0 -.3" size=".1" euler="0 -90 0" />
            <body pos="0 .3 -.3" euler="90 0 0">
                <joint name="left_wheel_joint" type="hinge" axis="0 0 -1" />
                <geom type="cylinder" size=".2 .05" rgba="0 .9 0 1" />
            </body>
            <body pos="0 -.3 -.3" euler="90 0 0">
                <joint name="right_wheel_joint" type="hinge" axis="0 0 -1" />
                <geom type="cylinder" size=".2 .05" rgba="0 .9 0 1" />
            </body>
            <body pos="0 0 .3">
                <joint name="caster_wheel_joint" type="ball" axis="0 0 -1" />
                <geom type="sphere" size=".2" rgba="0 0 .9 1" friction="0"/>
            </body>
        </body>
    </worldbody>
    <sensor>
        <framepos objtype="site" objname="marker" />
    </sensor>
    <actuator>
        <velocity name="left_wheel_servo" joint="left_wheel_joint" kv="100" />
        <velocity name="right_wheel_servo" joint="right_wheel_joint" kv="100" />
    </actuator>
</mujoco>